Workbook

Sheet Summary
A3: 行标签 | B3: 计数项:公司
A4: 成功 | B4: 65
A5: 无法自动获取下载链接，需手动下载 | B5: 3
A6: 自动下载失败，需手动下载 | B6: 8
A7: 未更新到2024Q3 | B7: 16
A8: 总计 | B8: 92

Sheet config
A1: control | B1: 公司 | C1: 类型 | D1: 网址 | E1: 进度 | F1: 备注 | G1: text_to_find | H1: xpath | I1: 季度 | J1: Y | K1: Q | L1: 保存地址 | M1: 保存文件名
A2: Y | B2: 平安寿险 | C2: 寿险 | D2: https://life.pingan.com/gongkaixinxipilu/changfunenglibaogao.jsp | E2: 成功 | G2: =$J2&"年第"&$K2&"季度" -> 2025年第2季度 | I2: 2025Q2 | J2: =LEFT(I2,4) -> 2025 | K2: =RIGHT(I2,1) -> 2 | L2: ="D:\文档\_工作相关\KPMG\CROSS II\"&I2 -> D:\文档\_工作相关\KPMG\CROSS II\2025Q2 | M2: =B2&I2&"偿付能力季度报告摘要.pdf" -> 平安寿险2025Q2偿付能力季度报告摘要.pdf
A3: Y | B3: 中国人寿 | C3: 寿险 | D3: https://www.e-chinalife.com/tzzgx/tzzgx/dqbg/cfnljbzy/ | E3: 成功 | G3: =$J3&"年"&$K3&"季度" -> 2025年2季度 | I3: 2025Q2 | J3: =LEFT(I3,4) -> 2025 | K3: =RIGHT(I3,1) -> 2 | L3: =$L$2 -> D:\文档\_工作相关\KPMG\CROSS II\2025Q2 | M3: =B3&I3&"偿付能力季度报告摘要.pdf" -> 中国人寿2025Q2偿付能力季度报告摘要.pdf
A4: Y | B4: 新华保险 | C4: 寿险 | D4: https://www.newchinalife.com/info/53474 | E4: 成功 | G4: =$J4&"年第"&CHOOSE($K4,"一","二","三","四")&"季度" -> 2025年第二季度 | I4: 2025Q2 | J4: =LEFT(I4,4) -> 2025 | K4: =RIGHT(I4,1) -> 2 | L4: =$L$2 -> D:\文档\_工作相关\KPMG\CROSS II\2025Q2 | M4: =B4&I4&"偿付能力季度报告摘要.pdf" -> 新华保险2025Q2偿付能力季度报告摘要.pdf
A5: Y | B5: 太保寿险 | C5: 寿险 | D5: https://life.cpic.com.cn/xrsbx/gkxxpl/cfnlxxzq/?subMenu=4&inSub=3 | E5: 成功 | G5: =$J5&"年第"&$K5&"季度" -> 2025年第2季度 | I5: 2025Q2 | J5: =LEFT(I5,4) -> 2025 | K5: =RIGHT(I5,1) -> 2 | L5: =$L$2 -> D:\文档\_工作相关\KPMG\CROSS II\2025Q2 | M5: =B5&I5&"偿付能力季度报告摘要.pdf" -> 太保寿险2025Q2偿付能力季度报告摘要.pdf
A6: Y | B6: 招商信诺 | C6: 寿险 | D6: https://www.cignacmb.com/xinxi/jibenxinxi/changfunengli.html | E6: 成功 | G6: =$J6&"年第"&$K6&"季度" -> 2025年第2季度 | I6: 2025Q2 | J6: =LEFT(I6,4) -> 2025 | K6: =RIGHT(I6,1) -> 2 | L6: =$L$2 -> D:\文档\_工作相关\KPMG\CROSS II\2025Q2 | M6: =B6&I6&"偿付能力季度报告摘要.pdf" -> 招商信诺2025Q2偿付能力季度报告摘要.pdf
A7: Y | B7: 泰康人寿 | C7: 寿险 | D7: https://www.taikanglife.com/publicinfonew/specialinfo/payinfonew/list_418_1.html | E7: 成功 | G7: =$J7&"年第"&$K7&"季度" -> 2025年第2季度 | I7: 2025Q2 | J7: =LEFT(I7,4) -> 2025 | K7: =RIGHT(I7,1) -> 2 | L7: =$L$2 -> D:\文档\_工作相关\KPMG\CROSS II\2025Q2 | M7: =B7&I7&"偿付能力季度报告摘要.pdf" -> 泰康人寿2025Q2偿付能力季度报告摘要.pdf
A8: Y | B8: 人保寿险 | C8: 寿险 | D8: https://www.picclife.cn/picclifewebsite/webfile/cfnljdbgzy/index.html | E8: 成功 | G8: =$J8&"年第"&$K8&"季度" -> 2025年第2季度 | I8: 2025Q2 | J8: =LEFT(I8,4) -> 2025 | K8: =RIGHT(I8,1) -> 2 | L8: =$L$2 -> D:\文档\_工作相关\KPMG\CROSS II\2025Q2 | M8: =B8&I8&"偿付能力季度报告摘要.pdf" -> 人保寿险2025Q2偿付能力季度报告摘要.pdf
A9: Y | B9: 中邮人寿 | C9: 寿险 | D9: https://www.chinapost-life.com/publish/publish4/publish4_4/ | E9: 成功 | G9: 2024年3季度 | I9: 2025Q2 | J9: =LEFT(I9,4) -> 2025 | K9: =RIGHT(I9,1) -> 2 | L9: =$L$2 -> D:\文档\_工作相关\KPMG\CROSS II\2025Q2 | M9: =B9&I9&"偿付能力季度报告摘要.pdf" -> 中邮人寿2025Q2偿付能力季度报告摘要.pdf
A10: Y | B10: 工银安盛 | C10: 寿险 | D10: https://www.icbc-axa.com/public/special_infor_temp/special_infor_3/publicList.jsp | E10: 成功 | G10: =$J10&"年第"&CHOOSE($K10,"一","二","三","四")&"季度" -> 2025年第二季度 | I10: 2025Q2 | J10: =LEFT(I10,4) -> 2025 | K10: =RIGHT(I10,1) -> 2 | L10: =$L$2 -> D:\文档\_工作相关\KPMG\CROSS II\2025Q2 | M10: =B10&I10&"偿付能力季度报告摘要.pdf" -> 工银安盛2025Q2偿付能力季度报告摘要.pdf
A11: Y | B11: 国华人寿 | C11: 寿险 | D11: https://www.95549.cn/pages/intro/xxpl05.shtml | E11: 成功 | G11: =$J11&"年"&$K11&"季度" -> 2025年2季度 | I11: 2025Q2 | J11: =LEFT(I11,4) -> 2025 | K11: =RIGHT(I11,1) -> 2 | L11: =$L$2 -> D:\文档\_工作相关\KPMG\CROSS II\2025Q2 | M11: =B11&I11&"偿付能力季度报告摘要.pdf" -> 国华人寿2025Q2偿付能力季度报告摘要.pdf
A12: Y | B12: 信泰人寿 | C12: 寿险 | D12: https://xintai.com/web/info/specialInfo/solvencyReport/periodicDisclosure/index.jsp | E12: 成功 | G12: =$J12&"年第"&$K12&"季度" -> 2025年第2季度 | I12: 2025Q2 | J12: =LEFT(I12,4) -> 2025 | K12: =RIGHT(I12,1) -> 2 | L12: =$L$2 -> D:\文档\_工作相关\KPMG\CROSS II\2025Q2 | M12: =B12&I12&"偿付能力季度报告摘要.pdf" -> 信泰人寿2025Q2偿付能力季度报告摘要.pdf
A13: Y | B13: 建信人寿 | C13: 寿险 | D13: https://www.ccb-life.com.cn/html/6182/3185/index.html | E13: 成功 | G13: =$J13&"年第"&$K13&"季度" -> 2025年第2季度 | I13: 2025Q2 | J13: =LEFT(I13,4) -> 2025 | K13: =RIGHT(I13,1) -> 2 | L13: =$L$2 -> D:\文档\_工作相关\KPMG\CROSS II\2025Q2 | M13: =B13&I13&"偿付能力季度报告摘要.pdf" -> 建信人寿2025Q2偿付能力季度报告摘要.pdf
A14: Y | B14: 民生人寿 | C14: 寿险 | D14: https://www.minshenglife.com/articleListOfChannel/357 | E14: 成功 | G14: =$J14&"年"&$K14&"季度" -> 2025年2季度 | I14: 2025Q2 | J14: =LEFT(I14,4) -> 2025 | K14: =RIGHT(I14,1) -> 2 | L14: =$L$2 -> D:\文档\_工作相关\KPMG\CROSS II\2025Q2 | M14: =B14&I14&"偿付能力季度报告摘要.pdf" -> 民生人寿2025Q2偿付能力季度报告摘要.pdf
A15: Y | B15: 中宏人寿 | C15: 寿险 | D15: https://www.manulife-sinochem.com/public-information/special/solvency | E15: 成功 | G15: =$I$2 -> 2025Q2 | I15: 2025Q2 | J15: =LEFT(I15,4) -> 2025 | K15: =RIGHT(I15,1) -> 2 | L15: =$L$2 -> D:\文档\_工作相关\KPMG\CROSS II\2025Q2 | M15: =B15&I15&"偿付能力季度报告摘要.pdf" -> 中宏人寿2025Q2偿付能力季度报告摘要.pdf
A16: Y | B16: 中英人寿 | C16: 寿险 | D16: http://www.aviva-cofco.com.cn/website/xxzx/gkxxpl/zxxx/cfnljdbgzy/cfnl1/list-1.shtml | E16: 成功 | G16: =$J16&"年第"&$K16&"季度" -> 2025年第2季度 | I16: 2025Q2 | J16: =LEFT(I16,4) -> 2025 | K16: =RIGHT(I16,1) -> 2 | L16: =$L$2 -> D:\文档\_工作相关\KPMG\CROSS II\2025Q2 | M16: =B16&I16&"偿付能力季度报告摘要.pdf" -> 中英人寿2025Q2偿付能力季度报告摘要.pdf
A17: Y | B17: 中美联泰 | C17: 寿险 | D17: https://www.metlife.com.cn/information-disclosure/public-information-disclosure/special-information/solvency-information | E17: 成功 | G17: =$J17&"年"&$K17&"季度" -> 2025年2季度 | I17: 2025Q2 | J17: =LEFT(I17,4) -> 2025 | K17: =RIGHT(I17,1) -> 2 | L17: =$L$2 -> D:\文档\_工作相关\KPMG\CROSS II\2025Q2 | M17: =B17&I17&"偿付能力季度报告摘要.pdf" -> 中美联泰2025Q2偿付能力季度报告摘要.pdf
A18: Y | B18: 中意人寿 | C18: 寿险 | D18: https://www.generalichina.com/cfnlnew/ | E18: 成功 | G18: =$J18&"年第"&$K18&"季度" -> 2025年第2季度 | I18: 2025Q2 | J18: =LEFT(I18,4) -> 2025 | K18: =RIGHT(I18,1) -> 2 | L18: =$L$2 -> D:\文档\_工作相关\KPMG\CROSS II\2025Q2 | M18: =B18&I18&"偿付能力季度报告摘要.pdf" -> 中意人寿2025Q2偿付能力季度报告摘要.pdf
A19: Y | B19: 长城人寿 | C19: 寿险 | D19: https://www.greatlife.cn/page/xxpl/cfnl/cfnl.shtml | E19: 成功 | G19: =$J19&"年第"&CHOOSE($K19,"一","二","三","四")&"季度" -> 2025年第二季度 | I19: 2025Q2 | J19: =LEFT(I19,4) -> 2025 | K19: =RIGHT(I19,1) -> 2 | L19: =$L$2 -> D:\文档\_工作相关\KPMG\CROSS II\2025Q2 | M19: =B19&I19&"偿付能力季度报告摘要.pdf" -> 长城人寿2025Q2偿付能力季度报告摘要.pdf
A20: Y | B20: 幸福人寿 | C20: 寿险 | D20: https://www.happyinsurance.com.cn/info/list_30_36_1.html#infoAnchor | E20: 成功 | G20: =$J20&"年第"&$K20&"季度" -> 2025年第2季度 | I20: 2025Q2 | J20: =LEFT(I20,4) -> 2025 | K20: =RIGHT(I20,1) -> 2 | L20: =$L$2 -> D:\文档\_工作相关\KPMG\CROSS II\2025Q2 | M20: =B20&I20&"偿付能力季度报告摘要.pdf" -> 幸福人寿2025Q2偿付能力季度报告摘要.pdf
A21: Y | B21: 光大永明 | C21: 寿险 | D21: https://www.sunlife-everbright.com/sleb/info/zxxx/cfnlxxplzl/index.html | E21: 成功 | G21: =$J21&"年"&$K21&"季度" -> 2025年2季度 | I21: 2025Q2 | J21: =LEFT(I21,4) -> 2025 | K21: =RIGHT(I21,1) -> 2 | L21: =$L$2 -> D:\文档\_工作相关\KPMG\CROSS II\2025Q2 | M21: =B21&I21&"偿付能力季度报告摘要.pdf" -> 光大永明2025Q2偿付能力季度报告摘要.pdf
A22: Y | B22: 英大人寿 | C22: 寿险 | D22: http://www.ydthlife.sgcc.com.cn/gkxxpl/zxxx/cfnlxx/index.shtml | E22: 成功 | G22: =$J22&"年"&$K22&"季度" -> 2025年2季度 | I22: 2025Q2 | J22: =LEFT(I22,4) -> 2025 | K22: =RIGHT(I22,1) -> 2 | L22: =$L$2 -> D:\文档\_工作相关\KPMG\CROSS II\2025Q2 | M22: =B22&I22&"偿付能力季度报告摘要.pdf" -> 英大人寿2025Q2偿付能力季度报告摘要.pdf
A23: Y | B23: 同方全球 | C23: 寿险 | D23: https://www.aegonthtf.com/gkxxpl/zxxx/cfnl/ | E23: 成功 | G23: =$J23&"年第"&$K23&"季度" -> 2025年第2季度 | I23: 2025Q2 | J23: =LEFT(I23,4) -> 2025 | K23: =RIGHT(I23,1) -> 2 | L23: =$L$2 -> D:\文档\_工作相关\KPMG\CROSS II\2025Q2 | M23: =B23&I23&"偿付能力季度报告摘要.pdf" -> 同方全球2025Q2偿付能力季度报告摘要.pdf
A24: Y | B24: 中荷人寿 | C24: 寿险 | D24: http://www.bob-cardif.com/xinxipilu/zhuanxiangxinxi/changfunenglixinxi/index.html | E24: 成功 | G24: =$J24&"年第"&$K24&"季度" -> 2025年第2季度 | I24: 2025Q2 | J24: =LEFT(I24,4) -> 2025 | K24: =RIGHT(I24,1) -> 2 | L24: =$L$2 -> D:\文档\_工作相关\KPMG\CROSS II\2025Q2 | M24: =B24&I24&"偿付能力季度报告摘要.pdf" -> 中荷人寿2025Q2偿付能力季度报告摘要.pdf
A25: Y | B25: 财信人寿 | C25: 寿险 | D25: https://life.hnchasing.com/web/info/iteminfo/cfnl/dqpl/index.jsp | E25: 成功 | G25: =$J25&"年"&$K25&"季度" -> 2025年2季度 | I25: 2025Q2 | J25: =LEFT(I25,4) -> 2025 | K25: =RIGHT(I25,1) -> 2 | L25: =$L$2 -> D:\文档\_工作相关\KPMG\CROSS II\2025Q2 | M25: =B25&I25&"偿付能力季度报告摘要.pdf" -> 财信人寿2025Q2偿付能力季度报告摘要.pdf
A26: Y | B26: 华泰人寿 | C26: 寿险 | D26: http://life.ehuatai.com/solvency.html | E26: 成功 | G26: =$J26&"年第"&CHOOSE($K26,"一","二","三","四")&"季度" -> 2025年第二季度 | I26: 2025Q2 | J26: =LEFT(I26,4) -> 2025 | K26: =RIGHT(I26,1) -> 2 | L26: =$L$2 -> D:\文档\_工作相关\KPMG\CROSS II\2025Q2 | M26: =B26&I26&"偿付能力季度报告摘要.pdf" -> 华泰人寿2025Q2偿付能力季度报告摘要.pdf
A27: Y | B27: 安联人寿 | C27: 寿险 | D27: https://www.allianz.com.cn/solvencyCapacity/AZ01005 | E27: 成功 | G27: =$J27&"年第"&$K27&"季度" -> 2025年第2季度 | I27: 2025Q2 | J27: =LEFT(I27,4) -> 2025 | K27: =RIGHT(I27,1) -> 2 | L27: =$L$2 -> D:\文档\_工作相关\KPMG\CROSS II\2025Q2 | M27: =B27&I27&"偿付能力季度报告摘要.pdf" -> 安联人寿2025Q2偿付能力季度报告摘要.pdf
A28: Y | B28: 北京人寿 | C28: 寿险 | D28: https://www.beijinglife.com.cn/publicInfo/solvency/ | E28: 成功 | G28: =$J28&"年"&$K28&"季度" -> 2025年2季度 | I28: 2025Q2 | J28: =LEFT(I28,4) -> 2025 | K28: =RIGHT(I28,1) -> 2 | L28: =$L$2 -> D:\文档\_工作相关\KPMG\CROSS II\2025Q2 | M28: =B28&I28&"偿付能力季度报告摘要.pdf" -> 北京人寿2025Q2偿付能力季度报告摘要.pdf
A29: Y | B29: 复星联合 | C29: 寿险 | D29: https://www.fosun-uhi.com/PublicInformation/SolvencyInformation/ | E29: 成功 | G29: =$J29&"年"&$K29&"季度" -> 2025年2季度 | I29: 2025Q2 | J29: =LEFT(I29,4) -> 2025 | K29: =RIGHT(I29,1) -> 2 | L29: =$L$2 -> D:\文档\_工作相关\KPMG\CROSS II\2025Q2 | M29: =B29&I29&"偿付能力季度报告摘要.pdf" -> 复星联合2025Q2偿付能力季度报告摘要.pdf
A30: Y | B30: 国联人寿 | C30: 寿险 | D30: https://www.guolian-life.com/companyNewsCenter.html?menuCode=107&grade=3 | E30: 成功 | G30: =$J30&"年第"&$K30&"季度" -> 2025年第2季度 | I30: 2025Q2 | J30: =LEFT(I30,4) -> 2025 | K30: =RIGHT(I30,1) -> 2 | L30: =$L$2 -> D:\文档\_工作相关\KPMG\CROSS II\2025Q2 | M30: =B30&I30&"偿付能力季度报告摘要.pdf" -> 国联人寿2025Q2偿付能力季度报告摘要.pdf
A31: Y | B31: 信美人寿 | C31: 寿险 | D31: https://www.trustlife.com/cms/html/payReport/ | E31: 成功 | G31: =$J31&"年第"&CHOOSE($K31,"一","二","三","四")&"季度" -> 2025年第二季度 | I31: 2025Q2 | J31: =LEFT(I31,4) -> 2025 | K31: =RIGHT(I31,1) -> 2 | L31: =$L$2 -> D:\文档\_工作相关\KPMG\CROSS II\2025Q2 | M31: =B31&I31&"偿付能力季度报告摘要.pdf" -> 信美人寿2025Q2偿付能力季度报告摘要.pdf
A32: Y | B32: 中华人寿 | C32: 寿险 | D32: https://life.cic.cn/redirect/info/repayMessage | E32: 成功 | G32: =$J32&"年"&CHOOSE($K32,"一","二","三","四")&"季度" -> 2025年二季度 | I32: 2025Q2 | J32: =LEFT(I32,4) -> 2025 | K32: =RIGHT(I32,1) -> 2 | L32: =$L$2 -> D:\文档\_工作相关\KPMG\CROSS II\2025Q2 | M32: =B32&I32&"偿付能力季度报告摘要.pdf" -> 中华人寿2025Q2偿付能力季度报告摘要.pdf
A33: Y | B33: 复星保德信 | C33: 寿险 | D33: https://www.pflife.com.cn/cpramericaFosun/publish/main/announce/specialInformation/payinfo/index.html | E33: 成功 | G33: =$J33&"年"&$K33&"季度" -> 2025年2季度 | I33: 2025Q2 | J33: =LEFT(I33,4) -> 2025 | K33: =RIGHT(I33,1) -> 2 | L33: =$L$2 -> D:\文档\_工作相关\KPMG\CROSS II\2025Q2 | M33: =B33&I33&"偿付能力季度报告摘要.pdf" -> 复星保德信2025Q2偿付能力季度报告摘要.pdf
A34: Y | B34: 汇丰人寿 | C34: 寿险 | D34: https://www.hsbcinsurance.com.cn/about-us/information-disclosure/special-information/#03 | E34: 成功 | G34: =$J34&"年第"&CHOOSE($K34,"一","二","三","四")&"季度偿付能力" -> 2025年第二季度偿付能力 | I34: 2025Q2 | J34: =LEFT(I34,4) -> 2025 | K34: =RIGHT(I34,1) -> 2 | L34: =$L$2 -> D:\文档\_工作相关\KPMG\CROSS II\2025Q2 | M34: =B34&I34&"偿付能力季度报告摘要.pdf" -> 汇丰人寿2025Q2偿付能力季度报告摘要.pdf
A35: Y | B35: 爱心人寿 | C35: 寿险 | D35: https://www.aixin-ins.com/gdgq/index.jhtml# | E35: 成功 | G35: =$J35&"年第"&CHOOSE($K35,"一","二","三","四")&"季度偿付能力" -> 2025年第二季度偿付能力 | I35: 2025Q2 | J35: =LEFT(I35,4) -> 2025 | K35: =RIGHT(I35,1) -> 2 | L35: =$L$2 -> D:\文档\_工作相关\KPMG\CROSS II\2025Q2 | M35: =B35&I35&"偿付能力季度报告摘要.pdf" -> 爱心人寿2025Q2偿付能力季度报告摘要.pdf
A36: Y | B36: 小康人寿 | C36: 寿险 | D36: http://www.sfli.com.cn/cms-web/front/sinofrench/plxx/zxxx/cfnl/cfnl@1.html | E36: 成功 | G36: =$J36&"年第"&$K36&"季度偿付能力" -> 2025年第2季度偿付能力 | I36: 2025Q2 | J36: =LEFT(I36,4) -> 2025 | K36: =RIGHT(I36,1) -> 2 | L36: =$L$2 -> D:\文档\_工作相关\KPMG\CROSS II\2025Q2 | M36: =B36&I36&"偿付能力季度报告摘要.pdf" -> 小康人寿2025Q2偿付能力季度报告摘要.pdf
A37: Y | B37: 北大方正 | C37: 寿险 | D37: https://www.pkufi.com/public-infomation/specialMsg/payCapacity?content=%E5%81%BF%E4%BB%98%E8%83%BD%E5%8A%9B | E37: 成功 | G37: =$J37&"年第"&$K37&"季度" -> 2025年第2季度 | I37: 2025Q2 | J37: =LEFT(I37,4) -> 2025 | K37: =RIGHT(I37,1) -> 2 | L37: =$L$2 -> D:\文档\_工作相关\KPMG\CROSS II\2025Q2 | M37: =B37&I37&"偿付能力季度报告摘要.pdf" -> 北大方正2025Q2偿付能力季度报告摘要.pdf
A38: Y | B38: 瑞泰人寿 | C38: 寿险 | D38: https://www.oldmutual-chnenergy.com/InfoPublish/tempReport/Solvency/ | E38: 成功 | G38: =$J38&"年第"&CHOOSE($K38,"一","二","三","四")&"季度" -> 2025年第二季度 | I38: 2025Q2 | J38: =LEFT(I38,4) -> 2025 | K38: =RIGHT(I38,1) -> 2 | L38: =$L$2 -> D:\文档\_工作相关\KPMG\CROSS II\2025Q2 | M38: =B38&I38&"偿付能力季度报告摘要.pdf" -> 瑞泰人寿2025Q2偿付能力季度报告摘要.pdf
A39: Y | B39: 国宝人寿 | C39: 寿险 | D39: https://www.panda-assets.com/PublicInfo/Index?TypeId=57 | E39: 成功 | G39: =$J39&"年第"&$K39&"季度" -> 2025年第2季度 | I39: 2025Q2 | J39: =LEFT(I39,4) -> 2025 | K39: =RIGHT(I39,1) -> 2 | L39: =$L$2 -> D:\文档\_工作相关\KPMG\CROSS II\2025Q2 | M39: =B39&I39&"偿付能力季度报告摘要.pdf" -> 国宝人寿2025Q2偿付能力季度报告摘要.pdf
A40: Y | B40: 和泰人寿 | C40: 寿险 | D40: https://www.htlic.com/info/special/liquidate | E40: 成功 | G40: =$J40&"年第"&CHOOSE($K40,"一","二","三","四")&"季度" -> 2025年第二季度 | I40: 2025Q2 | J40: =LEFT(I40,4) -> 2025 | K40: =RIGHT(I40,1) -> 2 | L40: =$L$2 -> D:\文档\_工作相关\KPMG\CROSS II\2025Q2 | M40: =B40&I40&"偿付能力季度报告摘要.pdf" -> 和泰人寿2025Q2偿付能力季度报告摘要.pdf
...
